[2024-02-27T04:07:32.704+0000] {scheduler_job_runner.py:1586} WARNING - Marking task instance <TaskInstance: welcome_dag.print_welcome scheduled__2024-02-25T23:00:00+00:00 [queued]> stuck in queued as failed. If the task instance has available retries, it will be retried.
[2024-02-27T04:07:32.984+0000] {scheduler_job_runner.py:781} ERROR - Executor reports task instance <TaskInstance: welcome_dag.print_welcome scheduled__2024-02-25T23:00:00+00:00 [queued]> finished (failed) although the task says it's queued. (Info: None) Was the task killed externally?
