[2024-02-25T16:56:08.293+0000] {taskinstance.py:1956} INFO - Dependencies all met for dep_context=non-requeueable deps ti=<TaskInstance: dag_generator_dag.execute_dag_generator manual__2024-02-25T16:56:07.199729+00:00 [queued]>
[2024-02-25T16:56:08.299+0000] {taskinstance.py:1956} INFO - Dependencies all met for dep_context=requeueable deps ti=<TaskInstance: dag_generator_dag.execute_dag_generator manual__2024-02-25T16:56:07.199729+00:00 [queued]>
[2024-02-25T16:56:08.299+0000] {taskinstance.py:2170} INFO - Starting attempt 1 of 1
[2024-02-25T16:56:08.307+0000] {taskinstance.py:2191} INFO - Executing <Task(PythonOperator): execute_dag_generator> on 2024-02-25 16:56:07.199729+00:00
[2024-02-25T16:56:08.311+0000] {standard_task_runner.py:60} INFO - Started process 374 to run task
[2024-02-25T16:56:08.313+0000] {standard_task_runner.py:87} INFO - Running: ['***', 'tasks', 'run', 'dag_generator_dag', 'execute_dag_generator', 'manual__2024-02-25T16:56:07.199729+00:00', '--job-id', '221', '--raw', '--subdir', 'DAGS_FOLDER/dag_gen.py', '--cfg-path', '/tmp/tmpyw4dwg2p']
[2024-02-25T16:56:08.314+0000] {standard_task_runner.py:88} INFO - Job 221: Subtask execute_dag_generator
[2024-02-25T16:56:08.345+0000] {task_command.py:423} INFO - Running <TaskInstance: dag_generator_dag.execute_dag_generator manual__2024-02-25T16:56:07.199729+00:00 [running]> on host 4bda982e80c0
[2024-02-25T16:56:08.411+0000] {taskinstance.py:2480} INFO - Exporting env vars: AIRFLOW_CTX_DAG_OWNER='***' AIRFLOW_CTX_DAG_ID='dag_generator_dag' AIRFLOW_CTX_TASK_ID='execute_dag_generator' AIRFLOW_CTX_EXECUTION_DATE='2024-02-25T16:56:07.199729+00:00' AIRFLOW_CTX_TRY_NUMBER='1' AIRFLOW_CTX_DAG_RUN_ID='manual__2024-02-25T16:56:07.199729+00:00'
[2024-02-25T16:56:08.412+0000] {taskinstance.py:2698} ERROR - Task failed with exception
Traceback (most recent call last):
  File "/home/airflow/.local/lib/python3.8/site-packages/airflow/models/taskinstance.py", line 433, in _execute_task
    result = execute_callable(context=context, **execute_callable_kwargs)
  File "/home/airflow/.local/lib/python3.8/site-packages/airflow/operators/python.py", line 199, in execute
    return_value = self.execute_callable()
  File "/home/airflow/.local/lib/python3.8/site-packages/airflow/operators/python.py", line 216, in execute_callable
    return self.python_callable(*self.op_args, **self.op_kwargs)
  File "/opt/airflow/dags/dag_gen.py", line 7, in run_dag_generator
    dag_gen()
  File "/opt/airflow/dags/dag_generator.py", line 8, in dag_gen
    template = env.get_template('templates/dag_template.jinja2')
  File "/home/airflow/.local/lib/python3.8/site-packages/jinja2/environment.py", line 1010, in get_template
    return self._load_template(name, globals)
  File "/home/airflow/.local/lib/python3.8/site-packages/jinja2/environment.py", line 969, in _load_template
    template = self.loader.load(self, name, self.make_globals(globals))
  File "/home/airflow/.local/lib/python3.8/site-packages/jinja2/loaders.py", line 125, in load
    source, filename, uptodate = self.get_source(environment, name)
  File "/home/airflow/.local/lib/python3.8/site-packages/jinja2/loaders.py", line 204, in get_source
    raise TemplateNotFound(template)
jinja2.exceptions.TemplateNotFound: templates/dag_template.jinja2
[2024-02-25T16:56:08.421+0000] {taskinstance.py:1138} INFO - Marking task as FAILED. dag_id=dag_generator_dag, task_id=execute_dag_generator, execution_date=20240225T165607, start_date=20240225T165608, end_date=20240225T165608
[2024-02-25T16:56:08.431+0000] {standard_task_runner.py:107} ERROR - Failed to execute job 221 for task execute_dag_generator (templates/dag_template.jinja2; 374)
[2024-02-25T16:56:08.445+0000] {local_task_job_runner.py:234} INFO - Task exited with return code 1
[2024-02-25T16:56:08.461+0000] {taskinstance.py:3280} INFO - 0 downstream tasks scheduled from follow-on schedule check
