[2024-02-28T09:11:46.277+0000] {taskinstance.py:1956} INFO - Dependencies all met for dep_context=non-requeueable deps ti=<TaskInstance: my_kubernetes_dag.task1 manual__2024-02-28T09:11:43.372656+00:00 [queued]>
[2024-02-28T09:11:46.285+0000] {taskinstance.py:1956} INFO - Dependencies all met for dep_context=requeueable deps ti=<TaskInstance: my_kubernetes_dag.task1 manual__2024-02-28T09:11:43.372656+00:00 [queued]>
[2024-02-28T09:11:46.285+0000] {taskinstance.py:2170} INFO - Starting attempt 1 of 2
[2024-02-28T09:11:46.299+0000] {taskinstance.py:2191} INFO - Executing <Task(KubernetesPodOperator): task1> on 2024-02-28 09:11:43.372656+00:00
[2024-02-28T09:11:46.304+0000] {standard_task_runner.py:60} INFO - Started process 472 to run task
[2024-02-28T09:11:46.307+0000] {standard_task_runner.py:87} INFO - Running: ['***', 'tasks', 'run', 'my_kubernetes_dag', 'task1', 'manual__2024-02-28T09:11:43.372656+00:00', '--job-id', '245', '--raw', '--subdir', 'DAGS_FOLDER/kubedag.py', '--cfg-path', '/tmp/tmphdnqhlb5']
[2024-02-28T09:11:46.308+0000] {standard_task_runner.py:88} INFO - Job 245: Subtask task1
[2024-02-28T09:11:46.344+0000] {task_command.py:423} INFO - Running <TaskInstance: my_kubernetes_dag.task1 manual__2024-02-28T09:11:43.372656+00:00 [running]> on host 4bda982e80c0
[2024-02-28T09:11:46.434+0000] {taskinstance.py:2480} INFO - Exporting env vars: AIRFLOW_CTX_DAG_OWNER='***' AIRFLOW_CTX_DAG_ID='my_kubernetes_dag' AIRFLOW_CTX_TASK_ID='task1' AIRFLOW_CTX_EXECUTION_DATE='2024-02-28T09:11:43.372656+00:00' AIRFLOW_CTX_TRY_NUMBER='1' AIRFLOW_CTX_DAG_RUN_ID='manual__2024-02-28T09:11:43.372656+00:00'
[2024-02-28T09:11:46.440+0000] {pod.py:926} INFO - Building pod task1-kfidmkx8 with labels: {'dag_id': 'my_kubernetes_dag', 'task_id': 'task1', 'run_id': 'manual__2024-02-28T091143.3726560000-8eae4150b', 'kubernetes_pod_operator': 'True', 'try_number': '1'}
[2024-02-28T09:11:46.448+0000] {pod.py:980} ERROR - Invalid kube-config file. No configuration found.
Traceback (most recent call last):
  File "/home/airflow/.local/lib/python3.8/site-packages/airflow/providers/cncf/kubernetes/hooks/kubernetes.py", line 255, in _get_default_client
    config.load_incluster_config(client_configuration=self.client_configuration)
  File "/home/airflow/.local/lib/python3.8/site-packages/kubernetes/config/incluster_config.py", line 118, in load_incluster_config
    InClusterConfigLoader(
  File "/home/airflow/.local/lib/python3.8/site-packages/kubernetes/config/incluster_config.py", line 54, in load_and_set
    self._load_config()
  File "/home/airflow/.local/lib/python3.8/site-packages/kubernetes/config/incluster_config.py", line 62, in _load_config
    raise ConfigException("Service host/port is not set.")
kubernetes.config.config_exception.ConfigException: Service host/port is not set.

During handling of the above exception, another exception occurred:

Traceback (most recent call last):
  File "/home/airflow/.local/lib/python3.8/site-packages/airflow/providers/cncf/kubernetes/operators/pod.py", line 539, in execute_sync
    self.pod_request_obj = self.build_pod_request_obj(context)
  File "/home/airflow/.local/lib/python3.8/site-packages/airflow/providers/cncf/kubernetes/operators/pod.py", line 935, in build_pod_request_obj
    "airflow_kpo_in_cluster": str(self.hook.is_in_cluster),
  File "/home/airflow/.local/lib/python3.8/site-packages/airflow/providers/cncf/kubernetes/hooks/kubernetes.py", line 271, in is_in_cluster
    self.api_client  # so we can determine if we are in_cluster or not
  File "/usr/local/lib/python3.8/functools.py", line 967, in __get__
    val = self.func(instance)
  File "/home/airflow/.local/lib/python3.8/site-packages/airflow/providers/cncf/kubernetes/hooks/kubernetes.py", line 279, in api_client
    return self.get_conn()
  File "/home/airflow/.local/lib/python3.8/site-packages/airflow/providers/cncf/kubernetes/hooks/kubernetes.py", line 247, in get_conn
    return self._get_default_client(cluster_context=cluster_context)
  File "/home/airflow/.local/lib/python3.8/site-packages/airflow/providers/cncf/kubernetes/hooks/kubernetes.py", line 260, in _get_default_client
    config.load_kube_config(
  File "/home/airflow/.local/lib/python3.8/site-packages/kubernetes/config/kube_config.py", line 808, in load_kube_config
    loader = _get_kube_config_loader(
  File "/home/airflow/.local/lib/python3.8/site-packages/kubernetes/config/kube_config.py", line 767, in _get_kube_config_loader
    raise ConfigException(
kubernetes.config.config_exception.ConfigException: Invalid kube-config file. No configuration found.

During handling of the above exception, another exception occurred:

Traceback (most recent call last):
  File "/home/airflow/.local/lib/python3.8/site-packages/airflow/providers/cncf/kubernetes/hooks/kubernetes.py", line 255, in _get_default_client
    config.load_incluster_config(client_configuration=self.client_configuration)
  File "/home/airflow/.local/lib/python3.8/site-packages/kubernetes/config/incluster_config.py", line 118, in load_incluster_config
    InClusterConfigLoader(
  File "/home/airflow/.local/lib/python3.8/site-packages/kubernetes/config/incluster_config.py", line 54, in load_and_set
    self._load_config()
  File "/home/airflow/.local/lib/python3.8/site-packages/kubernetes/config/incluster_config.py", line 62, in _load_config
    raise ConfigException("Service host/port is not set.")
kubernetes.config.config_exception.ConfigException: Service host/port is not set.

During handling of the above exception, another exception occurred:

Traceback (most recent call last):
  File "/home/airflow/.local/lib/python3.8/site-packages/airflow/providers/cncf/kubernetes/operators/pod.py", line 812, in patch_already_checked
    self.client.patch_namespaced_pod(
  File "/usr/local/lib/python3.8/functools.py", line 967, in __get__
    val = self.func(instance)
  File "/home/airflow/.local/lib/python3.8/site-packages/airflow/providers/cncf/kubernetes/operators/pod.py", line 474, in client
    return self.hook.core_v1_client
  File "/usr/local/lib/python3.8/functools.py", line 967, in __get__
    val = self.func(instance)
  File "/home/airflow/.local/lib/python3.8/site-packages/airflow/providers/cncf/kubernetes/hooks/kubernetes.py", line 283, in core_v1_client
    return client.CoreV1Api(api_client=self.api_client)
  File "/usr/local/lib/python3.8/functools.py", line 967, in __get__
    val = self.func(instance)
  File "/home/airflow/.local/lib/python3.8/site-packages/airflow/providers/cncf/kubernetes/hooks/kubernetes.py", line 279, in api_client
    return self.get_conn()
  File "/home/airflow/.local/lib/python3.8/site-packages/airflow/providers/cncf/kubernetes/hooks/kubernetes.py", line 247, in get_conn
    return self._get_default_client(cluster_context=cluster_context)
  File "/home/airflow/.local/lib/python3.8/site-packages/airflow/providers/cncf/kubernetes/hooks/kubernetes.py", line 260, in _get_default_client
    config.load_kube_config(
  File "/home/airflow/.local/lib/python3.8/site-packages/kubernetes/config/kube_config.py", line 808, in load_kube_config
    loader = _get_kube_config_loader(
  File "/home/airflow/.local/lib/python3.8/site-packages/kubernetes/config/kube_config.py", line 767, in _get_kube_config_loader
    raise ConfigException(
kubernetes.config.config_exception.ConfigException: Invalid kube-config file. No configuration found.
[2024-02-28T09:11:46.459+0000] {taskinstance.py:2698} ERROR - Task failed with exception
Traceback (most recent call last):
  File "/home/airflow/.local/lib/python3.8/site-packages/airflow/providers/cncf/kubernetes/hooks/kubernetes.py", line 255, in _get_default_client
    config.load_incluster_config(client_configuration=self.client_configuration)
  File "/home/airflow/.local/lib/python3.8/site-packages/kubernetes/config/incluster_config.py", line 118, in load_incluster_config
    InClusterConfigLoader(
  File "/home/airflow/.local/lib/python3.8/site-packages/kubernetes/config/incluster_config.py", line 54, in load_and_set
    self._load_config()
  File "/home/airflow/.local/lib/python3.8/site-packages/kubernetes/config/incluster_config.py", line 62, in _load_config
    raise ConfigException("Service host/port is not set.")
kubernetes.config.config_exception.ConfigException: Service host/port is not set.

During handling of the above exception, another exception occurred:

Traceback (most recent call last):
  File "/home/airflow/.local/lib/python3.8/site-packages/airflow/providers/cncf/kubernetes/operators/pod.py", line 539, in execute_sync
    self.pod_request_obj = self.build_pod_request_obj(context)
  File "/home/airflow/.local/lib/python3.8/site-packages/airflow/providers/cncf/kubernetes/operators/pod.py", line 935, in build_pod_request_obj
    "airflow_kpo_in_cluster": str(self.hook.is_in_cluster),
  File "/home/airflow/.local/lib/python3.8/site-packages/airflow/providers/cncf/kubernetes/hooks/kubernetes.py", line 271, in is_in_cluster
    self.api_client  # so we can determine if we are in_cluster or not
  File "/usr/local/lib/python3.8/functools.py", line 967, in __get__
    val = self.func(instance)
  File "/home/airflow/.local/lib/python3.8/site-packages/airflow/providers/cncf/kubernetes/hooks/kubernetes.py", line 279, in api_client
    return self.get_conn()
  File "/home/airflow/.local/lib/python3.8/site-packages/airflow/providers/cncf/kubernetes/hooks/kubernetes.py", line 247, in get_conn
    return self._get_default_client(cluster_context=cluster_context)
  File "/home/airflow/.local/lib/python3.8/site-packages/airflow/providers/cncf/kubernetes/hooks/kubernetes.py", line 260, in _get_default_client
    config.load_kube_config(
  File "/home/airflow/.local/lib/python3.8/site-packages/kubernetes/config/kube_config.py", line 808, in load_kube_config
    loader = _get_kube_config_loader(
  File "/home/airflow/.local/lib/python3.8/site-packages/kubernetes/config/kube_config.py", line 767, in _get_kube_config_loader
    raise ConfigException(
kubernetes.config.config_exception.ConfigException: Invalid kube-config file. No configuration found.

During handling of the above exception, another exception occurred:

Traceback (most recent call last):
  File "/home/airflow/.local/lib/python3.8/site-packages/airflow/models/taskinstance.py", line 433, in _execute_task
    result = execute_callable(context=context, **execute_callable_kwargs)
  File "/home/airflow/.local/lib/python3.8/site-packages/airflow/providers/cncf/kubernetes/operators/pod.py", line 534, in execute
    return self.execute_sync(context)
  File "/home/airflow/.local/lib/python3.8/site-packages/airflow/providers/cncf/kubernetes/operators/pod.py", line 574, in execute_sync
    self.cleanup(
  File "/home/airflow/.local/lib/python3.8/site-packages/airflow/providers/cncf/kubernetes/operators/pod.py", line 715, in cleanup
    raise AirflowException(
airflow.exceptions.AirflowException: Pod None returned a failure.
remote_pod: None
[2024-02-28T09:11:46.461+0000] {taskinstance.py:1138} INFO - Marking task as UP_FOR_RETRY. dag_id=my_kubernetes_dag, task_id=task1, execution_date=20240228T091143, start_date=20240228T091146, end_date=20240228T091146
[2024-02-28T09:11:46.474+0000] {standard_task_runner.py:107} ERROR - Failed to execute job 245 for task task1 (Pod None returned a failure.
remote_pod: None; 472)
[2024-02-28T09:11:46.519+0000] {local_task_job_runner.py:234} INFO - Task exited with return code 1
[2024-02-28T09:11:46.532+0000] {taskinstance.py:3280} INFO - 0 downstream tasks scheduled from follow-on schedule check
